<?xml version="1.0" encoding="UTF-8"?>
<testsuite name="TestWebApp-20250522021909" tests="3" file=".py" time="30.701" timestamp="2025-05-22T02:19:39" failures="0" errors="1" skipped="0">
	<testcase classname="TestWebApp" name="test_contact_form_fields_present" time="9.083" timestamp="2025-05-22T02:19:18" file="test_selenium.py" line="31"/>
	<testcase classname="TestWebApp" name="test_homepage_title" time="7.299" timestamp="2025-05-22T02:19:39" file="test_selenium.py" line="21"/>
	<testcase classname="TestWebApp" name="test_contact_form_submission" time="14.320" timestamp="2025-05-22T02:19:32" file="test_selenium.py" line="45">
		<error type="UnexpectedAlertPresentException" message="Alert Text: Mensaje enviado con éxito
Message: unexpected alert open: {Alert text : Mensaje enviado con éxito}
  (Session info: chrome=136.0.7103.113)
Stacktrace:
#0 0x55de74d3975a &lt;unknown&gt;
#1 0x55de747dc0a0 &lt;unknown&gt;
#2 0x55de74879cd1 &lt;unknown&gt;
#3 0x55de74853173 &lt;unknown&gt;
#4 0x55de7481fd4b &lt;unknown&gt;
#5 0x55de748209b1 &lt;unknown&gt;
#6 0x55de74cfe90b &lt;unknown&gt;
#7 0x55de74d0280a &lt;unknown&gt;
#8 0x55de74ce6662 &lt;unknown&gt;
#9 0x55de74d03394 &lt;unknown&gt;
#10 0x55de74ccb49f &lt;unknown&gt;
#11 0x55de74d27538 &lt;unknown&gt;
#12 0x55de74d27716 &lt;unknown&gt;
#13 0x55de74d385c6 &lt;unknown&gt;
#14 0x7f24bdfc9aa4 &lt;unknown&gt;
#15 0x7f24be056c3c &lt;unknown&gt;
"><![CDATA[Traceback (most recent call last):
  File "/code/test_selenium.py", line 66, in test_contact_form_submission
    raise e
  File "/code/test_selenium.py", line 61, in test_contact_form_submission
    current_url = self.driver.current_url
                  ^^^^^^^^^^^^^^^^^^^^^^^
  File "/usr/local/lib/python3.12/site-packages/selenium/webdriver/remote/webdriver.py", line 579, in current_url
    return self.execute(Command.GET_CURRENT_URL)["value"]
           ^^^^^^^^^^^^^^^^^^^^^^^^^^^^^^^^^^^^^
  File "/usr/local/lib/python3.12/site-packages/selenium/webdriver/remote/webdriver.py", line 448, in execute
    self.error_handler.check_response(response)
  File "/usr/local/lib/python3.12/site-packages/selenium/webdriver/remote/errorhandler.py", line 231, in check_response
    raise exception_class(message, screen, stacktrace, alert_text)  # type: ignore[call-arg]  # mypy is not smart enough here
    ^^^^^^^^^^^^^^^^^^^^^^^^^^^^^^^^^^^^^^^^^^^^^^^^^^^^^^^^^^^^^^
selenium.common.exceptions.UnexpectedAlertPresentException: Alert Text: Mensaje enviado con éxito
Message: unexpected alert open: {Alert text : Mensaje enviado con éxito}
  (Session info: chrome=136.0.7103.113)
Stacktrace:
#0 0x55de74d3975a <unknown>
#1 0x55de747dc0a0 <unknown>
#2 0x55de74879cd1 <unknown>
#3 0x55de74853173 <unknown>
#4 0x55de7481fd4b <unknown>
#5 0x55de748209b1 <unknown>
#6 0x55de74cfe90b <unknown>
#7 0x55de74d0280a <unknown>
#8 0x55de74ce6662 <unknown>
#9 0x55de74d03394 <unknown>
#10 0x55de74ccb49f <unknown>
#11 0x55de74d27538 <unknown>
#12 0x55de74d27716 <unknown>
#13 0x55de74d385c6 <unknown>
#14 0x7f24bdfc9aa4 <unknown>
#15 0x7f24be056c3c <unknown>

]]></error>
	</testcase>
</testsuite>
